The solution involves robust error handling throughout the nested asynchronous operations.  This ensures that any error at any level is properly caught and either displayed to the user or logged for debugging.  Always wrap asynchronous operations in `try...catch` blocks, and handle any rejected promises.

```javascript
// pages/index.js (Server Component)
export default async function Home() {
  let data = null;
  try {
    data = await fetchData();
  } catch (error) {
    console.error('Error fetching data:', error);
    data = { error: 'Failed to fetch data' }; //Provide fallback value for client
  }
  return (
    <div>{JSON.stringify(data)}</div>
  );
}

async function fetchData() {
  try {
    const response = await fetch('/api/data');
    const json = await response.json();
    const nestedData = await processNestedData(json);
    return nestedData;
  } catch (error) {
    throw new Error(`Error in fetchData: ${error.message}`);
  }
}

async function processNestedData(data) {
  try {
    // ...complex async operations...
    if (data.id === 1) { //Simulate error
      throw new Error('Simulated error in nested function');
    }
    return data;
  } catch (error) {
    throw new Error(`Error in processNestedData: ${error.message}`);
  }
}
```

This improved version ensures that any error is caught and handled appropriately, preventing silent failures and providing better debugging information.